2024-06-30 12:37:17,355 - utils - ERROR - type object 'Meat' has no attribute 'query'
Traceback (most recent call last):
  File "/Users/yang-eunseo/Desktop/test-backend/flask/api/get_api.py", line 31, in getMeatData
    get_range_meat_data(db_session, 0, Meat.query.count())
AttributeError: type object 'Meat' has no attribute 'query'
2024-06-30 12:41:55,125 - utils - ERROR - 'NoneType' object has no attribute 'query'
Traceback (most recent call last):
  File "/Users/yang-eunseo/Desktop/test-backend/flask/db/db_controller.py", line 796, in _get_users_by_type
    users = db_session.query(User).all()
AttributeError: 'NoneType' object has no attribute 'query'

During handling of the above exception, another exception occurred:

Traceback (most recent call last):
  File "/Users/yang-eunseo/Desktop/test-backend/flask/api/user_api.py", line 50, in read_user_data
    result = _get_users_by_type(db_session)
  File "/Users/yang-eunseo/Desktop/test-backend/flask/db/db_controller.py", line 812, in _get_users_by_type
    raise Exception(str(e))
Exception: 'NoneType' object has no attribute 'query'
2024-06-30 13:35:19,839 - utils - ERROR - 'NoneType' object has no attribute 'query'
Traceback (most recent call last):
  File "/Users/yang-eunseo/Desktop/test-backend/flask/db/db_controller.py", line 796, in _get_users_by_type
    users = db_session.query(User).all()
AttributeError: 'NoneType' object has no attribute 'query'

During handling of the above exception, another exception occurred:

Traceback (most recent call last):
  File "/Users/yang-eunseo/Desktop/test-backend/flask/api/user_api.py", line 50, in read_user_data
    result = _get_users_by_type(db_session)
  File "/Users/yang-eunseo/Desktop/test-backend/flask/db/db_controller.py", line 819, in _get_users_by_type
    raise Exception(str(e))
Exception: 'NoneType' object has no attribute 'query'
2024-06-30 18:55:50,092 - utils - ERROR - 'Flask' object has no attribute 'db_session'
Traceback (most recent call last):
  File "/Users/yang-eunseo/Desktop/test-backend/test-flask/api/user_api.py", line 43, in read_user_data
    db_session = current_app.db_session
AttributeError: 'Flask' object has no attribute 'db_session'
2024-06-30 18:55:57,029 - utils - ERROR - 'Flask' object has no attribute 'db_session'
Traceback (most recent call last):
  File "/Users/yang-eunseo/Desktop/test-backend/test-flask/api/user_api.py", line 43, in read_user_data
    db_session = current_app.db_session
AttributeError: 'Flask' object has no attribute 'db_session'
2024-06-30 19:02:29,320 - utils - ERROR - 'Flask' object has no attribute 'db_session'
Traceback (most recent call last):
  File "/Users/yang-eunseo/Desktop/test-backend/test-flask/api/user_api.py", line 43, in read_user_data
    db_session = current_app.db_session
AttributeError: 'Flask' object has no attribute 'db_session'
2024-06-30 19:36:15,754 - utils - ERROR - 'Flask' object has no attribute 'db_session'
Traceback (most recent call last):
  File "/Users/yang-eunseo/Desktop/test-backend/test-flask/api/user_api.py", line 43, in read_user_data
    db_session = current_app.db_session
AttributeError: 'Flask' object has no attribute 'db_session'
2024-06-30 19:36:25,824 - utils - ERROR - 'Flask' object has no attribute 'db_session'
Traceback (most recent call last):
  File "/Users/yang-eunseo/Desktop/test-backend/test-flask/api/user_api.py", line 43, in read_user_data
    db_session = current_app.db_session
AttributeError: 'Flask' object has no attribute 'db_session'
2024-06-30 20:01:30,302 - utils - ERROR - 415 Unsupported Media Type: Did not attempt to load JSON data because the request Content-Type was not 'application/json'.
Traceback (most recent call last):
  File "/Users/yang-eunseo/Desktop/test-backend/test-flask/api/user_api.py", line 32, in register_user_data
    data = request.get_json()
  File "/Users/yang-eunseo/Desktop/test-backend/venv/lib/python3.9/site-packages/werkzeug/wrappers/request.py", line 601, in get_json
    return self.on_json_loading_failed(None)
  File "/Users/yang-eunseo/Desktop/test-backend/venv/lib/python3.9/site-packages/flask/wrappers.py", line 130, in on_json_loading_failed
    return super().on_json_loading_failed(e)
  File "/Users/yang-eunseo/Desktop/test-backend/venv/lib/python3.9/site-packages/werkzeug/wrappers/request.py", line 644, in on_json_loading_failed
    raise UnsupportedMediaType(
werkzeug.exceptions.UnsupportedMediaType: 415 Unsupported Media Type: Did not attempt to load JSON data because the request Content-Type was not 'application/json'.
2024-06-30 20:04:31,359 - utils - ERROR - '<' not supported between instances of 'NoneType' and 'str'
Traceback (most recent call last):
  File "/Users/yang-eunseo/Desktop/test-backend/test-flask/api/user_api.py", line 61, in read_user_data
    return jsonify(result), 200
  File "/Users/yang-eunseo/Desktop/test-backend/venv/lib/python3.9/site-packages/flask/json/__init__.py", line 170, in jsonify
    return current_app.json.response(*args, **kwargs)
  File "/Users/yang-eunseo/Desktop/test-backend/venv/lib/python3.9/site-packages/flask/json/provider.py", line 215, in response
    f"{self.dumps(obj, **dump_args)}\n", mimetype=self.mimetype
  File "/Users/yang-eunseo/Desktop/test-backend/venv/lib/python3.9/site-packages/flask/json/provider.py", line 180, in dumps
    return json.dumps(obj, **kwargs)
  File "/Library/Developer/CommandLineTools/Library/Frameworks/Python3.framework/Versions/3.9/lib/python3.9/json/__init__.py", line 234, in dumps
    return cls(
  File "/Library/Developer/CommandLineTools/Library/Frameworks/Python3.framework/Versions/3.9/lib/python3.9/json/encoder.py", line 201, in encode
    chunks = list(chunks)
  File "/Library/Developer/CommandLineTools/Library/Frameworks/Python3.framework/Versions/3.9/lib/python3.9/json/encoder.py", line 431, in _iterencode
    yield from _iterencode_dict(o, _current_indent_level)
  File "/Library/Developer/CommandLineTools/Library/Frameworks/Python3.framework/Versions/3.9/lib/python3.9/json/encoder.py", line 353, in _iterencode_dict
    items = sorted(dct.items())
TypeError: '<' not supported between instances of 'NoneType' and 'str'
2024-06-30 20:05:03,857 - utils - ERROR - '<' not supported between instances of 'NoneType' and 'str'
Traceback (most recent call last):
  File "/Users/yang-eunseo/Desktop/test-backend/test-flask/api/user_api.py", line 61, in read_user_data
    return jsonify(result), 200
  File "/Users/yang-eunseo/Desktop/test-backend/venv/lib/python3.9/site-packages/flask/json/__init__.py", line 170, in jsonify
    return current_app.json.response(*args, **kwargs)
  File "/Users/yang-eunseo/Desktop/test-backend/venv/lib/python3.9/site-packages/flask/json/provider.py", line 215, in response
    f"{self.dumps(obj, **dump_args)}\n", mimetype=self.mimetype
  File "/Users/yang-eunseo/Desktop/test-backend/venv/lib/python3.9/site-packages/flask/json/provider.py", line 180, in dumps
    return json.dumps(obj, **kwargs)
  File "/Library/Developer/CommandLineTools/Library/Frameworks/Python3.framework/Versions/3.9/lib/python3.9/json/__init__.py", line 234, in dumps
    return cls(
  File "/Library/Developer/CommandLineTools/Library/Frameworks/Python3.framework/Versions/3.9/lib/python3.9/json/encoder.py", line 201, in encode
    chunks = list(chunks)
  File "/Library/Developer/CommandLineTools/Library/Frameworks/Python3.framework/Versions/3.9/lib/python3.9/json/encoder.py", line 431, in _iterencode
    yield from _iterencode_dict(o, _current_indent_level)
  File "/Library/Developer/CommandLineTools/Library/Frameworks/Python3.framework/Versions/3.9/lib/python3.9/json/encoder.py", line 353, in _iterencode_dict
    items = sorted(dct.items())
TypeError: '<' not supported between instances of 'NoneType' and 'str'
2024-06-30 22:51:22,443 - utils - ERROR - '<' not supported between instances of 'NoneType' and 'str'
Traceback (most recent call last):
  File "/Users/yang-eunseo/Desktop/test-server/test-backend/test-flask/api/user_api.py", line 60, in read_user_data
    return jsonify(result), 200
  File "/Users/yang-eunseo/Library/Python/3.9/lib/python/site-packages/flask/json/__init__.py", line 170, in jsonify
    return current_app.json.response(*args, **kwargs)  # type: ignore[return-value]
  File "/Users/yang-eunseo/Library/Python/3.9/lib/python/site-packages/flask/json/provider.py", line 214, in response
    f"{self.dumps(obj, **dump_args)}\n", mimetype=self.mimetype
  File "/Users/yang-eunseo/Library/Python/3.9/lib/python/site-packages/flask/json/provider.py", line 179, in dumps
    return json.dumps(obj, **kwargs)
  File "/Library/Developer/CommandLineTools/Library/Frameworks/Python3.framework/Versions/3.9/lib/python3.9/json/__init__.py", line 234, in dumps
    return cls(
  File "/Library/Developer/CommandLineTools/Library/Frameworks/Python3.framework/Versions/3.9/lib/python3.9/json/encoder.py", line 201, in encode
    chunks = list(chunks)
  File "/Library/Developer/CommandLineTools/Library/Frameworks/Python3.framework/Versions/3.9/lib/python3.9/json/encoder.py", line 431, in _iterencode
    yield from _iterencode_dict(o, _current_indent_level)
  File "/Library/Developer/CommandLineTools/Library/Frameworks/Python3.framework/Versions/3.9/lib/python3.9/json/encoder.py", line 353, in _iterencode_dict
    items = sorted(dct.items())
TypeError: '<' not supported between instances of 'NoneType' and 'str'
2024-06-30 23:15:09,562 - utils - ERROR - 415 Unsupported Media Type: Did not attempt to load JSON data because the request Content-Type was not 'application/json'.
Traceback (most recent call last):
  File "/Users/yang-eunseo/Desktop/test-server/test-backend/test-flask/api/user_api.py", line 221, in login
    data = request.get_json()
  File "/Users/yang-eunseo/Library/Python/3.9/lib/python/site-packages/werkzeug/wrappers/request.py", line 604, in get_json
    return self.on_json_loading_failed(None)
  File "/Users/yang-eunseo/Library/Python/3.9/lib/python/site-packages/flask/wrappers.py", line 131, in on_json_loading_failed
    return super().on_json_loading_failed(e)
  File "/Users/yang-eunseo/Library/Python/3.9/lib/python/site-packages/werkzeug/wrappers/request.py", line 647, in on_json_loading_failed
    raise UnsupportedMediaType(
werkzeug.exceptions.UnsupportedMediaType: 415 Unsupported Media Type: Did not attempt to load JSON data because the request Content-Type was not 'application/json'.
2024-06-30 23:59:19,560 - utils - ERROR - 415 Unsupported Media Type: Did not attempt to load JSON data because the request Content-Type was not 'application/json'.
Traceback (most recent call last):
  File "/Users/yang-eunseo/Desktop/test-server/test-backend/test-flask/app.py", line 29, in login
    data = request.get_json()
  File "/Users/yang-eunseo/Library/Python/3.9/lib/python/site-packages/werkzeug/wrappers/request.py", line 604, in get_json
    return self.on_json_loading_failed(None)
  File "/Users/yang-eunseo/Library/Python/3.9/lib/python/site-packages/flask/wrappers.py", line 131, in on_json_loading_failed
    return super().on_json_loading_failed(e)
  File "/Users/yang-eunseo/Library/Python/3.9/lib/python/site-packages/werkzeug/wrappers/request.py", line 647, in on_json_loading_failed
    raise UnsupportedMediaType(
werkzeug.exceptions.UnsupportedMediaType: 415 Unsupported Media Type: Did not attempt to load JSON data because the request Content-Type was not 'application/json'.
